Workbook

Sheet Items
A1: Item ID | B1: Name | C1: Description | D1: Image | E1: Cost | F1: Price
A2: item-123 | B2: 1 1/4 EG Nails | C2: 15-18 Sq. per box | D2: https://encrypted-tbn3.gstatic.com/shopping?q=tbn:ANd9GcS_7eWm-LY8KpN1vdKwV2RIR6dolS2dTEJHWgkx3Uvums0B9v3WNMrB5OvBHE5NK9gpcAPYDYMlUmdkHMWEbD8DIaylxnDFfCJjmRC9Sn6dh38yPghoI20JEA | E2: 27.5 | F2: 64.9
A3: item-124 | B3: Buttom Caps (plastic) | C3: 25-35 SQ per bucket by pitch | D3: https://encrypted-tbn0.gstatic.com/shopping?q=tbn:ANd9GcQ1yuW7vg_MsldvgGj0y6wzwUL4kUtTtycnViW9RLxMuJZnL40DFI4ij8d6-nBO0R8o4iytQf8oIFuGlGvMTrxQd0Pb9k93AllbPsx7L_meRwQAIFWrOC8ArN6OVGZ6hMLeKOnUYVoBY_U&usqp=CAc | E3: 16.5 | F3: 29.15
A4: item-125 | B4: RCRS Syn Felt | C4: 10 Sq | D4: https://photos.fife.usercontent.google.com/pw/AP1GczNY46QB5i9LjktiAVdMllW_jaIex15ncztJGTIB0WQ1CqtR-TYANkQonA=w635-h411-no?authuser=0 | E4: 66 | F4: 79.86
A5: item-126 | B5: Ice & Water Shield | C5: Peel and Stick, 67LF, 2 SQ. ,200 SQFT | D5: https://encrypted-tbn2.gstatic.com/shopping?q=tbn:ANd9GcSzOAw4Aj4ZG4pmhJXJCLg51yxr0Y35tAQPTWdwS6VgVdcnqncXijRIT87s4ob1SRGXCrVFgatcJuU0LI_CIeV6FbuY7TRsNPawLxZuSjsLRZmPfDmU70mM5j9vfzUkoB6Z-ddBu9Q&usqp=CAc | E5: 62.7 | F5: 114.22
A6: item-127 | B6: Ridge Vent 4LF | D6: https://encrypted-tbn0.gstatic.com/shopping?q=tbn:ANd9GcSHRVpFg9rrzAiq3H3cXgKDHQ3oBmdhOLjeikFgLv_Tu6RdK6wMwgbf_Sq-KoNhq9R0p7DezHvz7bnClmFQcIfnb2_K-tL6GF9b7svBQ42aPy90DiHbKnVxkLZXGeZ_yyN42eoS4sgkGQ&usqp=CAc | E6: 7.15 | F6: 10.2
A7: item-128 | B7: 1 1/2" Black Bullet Boot | D7: https://i.ebayimg.com/images/g/BCoAAOSwddRjhlWU/s-l1200.jpg | E7: 16.67 | F7: 20.89
A8: item-129 | B8: 2" Black Bullet Boot | D8: https://i.ebayimg.com/images/g/BCoAAOSwddRjhlWU/s-l1200.jpg | E8: 17.77 | F8: 22.54
A9: item-130 | B9: 3" Black Bullet Boot | D9: https://i.ebayimg.com/images/g/BCoAAOSwddRjhlWU/s-l1200.jpg | E9: 20.19 | F9: 38.29
A10: item-131 | B10: 4" Black Bullet Boot | D10: https://i.ebayimg.com/images/g/BCoAAOSwddRjhlWU/s-l1200.jpg | E10: 37.48 | F10: 42.5
A11: item-132 | B11: Sealant | D11: https://www.topshieldproducts.com/siteassets/ts-product-images/sealants--paints/selants/elastomeric-sealant-clear_default.jpg | E11: 9.35 | F11: 10
A12: item-133 | B12: Zipper boot | D12: https://images.thdstatic.com/productImages/3e28c711-45ad-4010-926e-578b9e99684c/svn/oatey-vent-pipe-flashing-14751-e1_600.jpg | E12: 37.4 | F12: 48

Sheet Login Check
A1: User Name | B1: Password | C1: Login Status | D1: Timestamp

Sheet Users
A1: uid | B1: user name | C1: user email | D1: user role | E1: ACTIVE | F1: PASSSWORD
A2: RVR-131 | B2: SARAHILL | C2: SARA@RIVERCITYROOFINGSOLUTIONS.COM | D2: ADMIN | E2: TRUE | F2: ChangeMe123!
A3: RVR-132 | B3: DESTINMcCURY | C3: DESTIN@RIVERCITYROOFINGSOLUTIONS.COM | D3: MANAGER | E3: TRUE | F3: ChangeMe123!
A4: RVR-133 | B4: TIAMORRIS | C4: TIA@RIVERCITYROOFINGSOLUTIONS.COM | D4: MANAGER | E4: TRUE | F4: ChangeMe123!
A5: RVR-134 | B5: BARTROBERTS | C5: BART@RIVERCITYROOFINGSOLUTIONS.COM | D5: MANAGER | E5: TRUE | F5: ChangeMe123!
A6: RVR-135 | B6: MICHAELMUSE | C6: MICHAELMUSE@RIVERCITYROOFINGSOLUTIONS.COM | D6: ADMIN | E6: TRUE | F6: ChangeMe123!
A7: RVR-136 | B7: RICHARDGEAHR | C7: RICHARD@RIVERCITYROOFINGSOLUTIONS.COM | D7: USER | E7: TRUE | F7: ChangeMe123!
A8: RVR-137 | B8: JOHNCORDONIS | C8: JOHN@RIVERCITYROOFINGSOLUTIONS.COM | D8: MANAGER | E8: TRUE | F8: ChangeMe123!
A9: RVR-138 | B9: CRIS MUSE | C9: CHRRISMUSE@RIVERCITYROOFINGSOLUTIONS.COM | D9: USER | E9: TRUE | F9: ChangeMe123!
A10: RVR-139 | B10: admin | C10: admin | D10: ADMIN | E10: TRUE | F10: admin
A11: a8ad2e33 | B11: Tae Orr | C11: tae@rivercityroofingsolutions.com | D11: USER | E11: TRUE | F11: ChangeMe123!
A12: 18d30481

Sheet SalesOrder
A1: Sales Representative | B1: Job Number | C1: Job Name | D1: Customer Name | E1: Customer Address | F1: Material Order # | G1: Order Date | H1: Item Description | I1: Unit of Measure | J1: Quantity

Sheet Inventory
A1: Inventory ID | B1: Item ID | C1: DateTime | D1: Amount | E1: R# | F1: Price | G1: Cost | H1: Delivery Photo
A2: f85d1e74 | B2: item-132 | C2: 45965.702 | D2: -3 | E2: 10785 | G2: =IF(D2<>"", VLOOKUP(B2, Items!A:F, 6, FALSE) * D2, "") -> -30
A3: fa511fdd | B3: item-130 | C3: 45965.702 | D3: -2 | E3: 10785 | G3: =IF(D3<>"", VLOOKUP(B3, Items!A:F, 6, FALSE) * D3, "") -> -76.58
A4: 7d9cfccf | B4: item-125 | C4: 45965.701 | D4: -5 | E4: 10785 | G4: =IF(D4<>"", VLOOKUP(B4, Items!A:F, 6, FALSE) * D4, "") -> -399.3
A5: c8bd5cf1 | B5: item-126 | C5: 45965.701 | D5: -2 | E5: 10785 | G5: =IF(D5<>"", VLOOKUP(B5, Items!A:F, 6, FALSE) * D5, "") -> -228.44
A6: 25af6fe9 | B6: item-127 | C6: 45965.701 | D6: -32 | E6: 10785 | G6: =IF(D6<>"", VLOOKUP(B6, Items!A:F, 6, FALSE) * D6, "") -> -326.4
A7: baf3ce0a | B7: item-124 | C7: 45965.701 | D7: -2 | E7: 10785 | G7: =IF(D7<>"", VLOOKUP(B7, Items!A:F, 6, FALSE) * D7, "") -> -58.3
A8: 49824910 | B8: item-123 | C8: 45965.701 | D8: -3 | E8: 10785 | G8: =IF(D8<>"", VLOOKUP(B8, Items!A:F, 6, FALSE) * D8, "") -> -194.7
A9: 7d6f2f6a | B9: item-126 | C9: 45965.621 | D9: -7 | E9: 10710 | G9: =IF(D9<>"", VLOOKUP(B9, Items!A:F, 6, FALSE) * D9, "") -> -799.54
A10: 5ad7b774 | B10: item-133 | C10: 45965.621 | D10: -1 | E10: 10710 | G10: =IF(D10<>"", VLOOKUP(B10, Items!A:F, 6, FALSE) * D10, "") -> -48
A11: a848d777 | B11: item-132 | C11: 45965.62 | D11: -7 | E11: 10710 | G11: =IF(D11<>"", VLOOKUP(B11, Items!A:F, 6, FALSE) * D11, "") -> -70
A12: e40a3481 | B12: item-130 | C12: 45965.62 | D12: -1 | E12: 10710 | G12: =IF(D12<>"", VLOOKUP(B12, Items!A:F, 6, FALSE) * D12, "") -> -38.29
A13: 14e9116c | B13: item-129 | C13: 45965.62 | D13: -1 | E13: 10710 | G13: =IF(D13<>"", VLOOKUP(B13, Items!A:F, 6, FALSE) * D13, "") -> -22.54
... A296: 7293630e | B296: item-125 | C296: 45910.36 | D296: 128 | E296: 1234 | G296: =IF(D296<>"", VLOOKUP(B296, Items!A:F, 6, FALSE) * D296, "") -> 10222.08
A297: 2105297 | B297: item-123 | C297: 45910.36 | D297: 48 | E297: 1234 | G297: =IF(D297<>"", VLOOKUP(B297, Items!A:F, 6, FALSE) * D297, "") -> 3115.2
A298: 220dbec3 | B298: item-132 | C298: 45909.491 | D298: -2 | E298: 10519 | G298: =IF(D298<>"", VLOOKUP(B298, Items!A:F, 6, FALSE) * D298, "") -> -20
A299: 0b375a8f | B299: item-128 | C299: 45909.491 | D299: -2 | E299: 10519 | G299: =IF(D299<>"", VLOOKUP(B299, Items!A:F, 6, FALSE) * D299, "") -> -41.78
A300: 87f101a7 | B300: item-125 | C300: 45909.491 | D300: -3 | E300: 10519 | G300: =IF(D300<>"", VLOOKUP(B300, Items!A:F, 6, FALSE) * D300, "") -> -239.58
A301: 47baded6 | B301: item-126 | C301: 45909.491 | D301: -1 | E301: 10519 | G301: =IF(D301<>"", VLOOKUP(B301, Items!A:F, 6, FALSE) * D301, "") -> -114.22
A302: b43e4d30 | B302: item-124 | C302: 45909.491 | D302: -1 | E302: 10519 | G302: =IF(D302<>"", VLOOKUP(B302, Items!A:F, 6, FALSE) * D302, "") -> -29.15
A303: 0080fc83 | B303: item-123 | C303: 45909.491 | D303: -2 | E303: 10519 | G303: =IF(D303<>"", VLOOKUP(B303, Items!A:F, 6, FALSE) * D303, "") -> -129.8
A304: 51c67df9 | B304: item-127 | C304: 45909.461 | D304: 4 | E304: 10130 | G304: =IF(D304<>"", VLOOKUP(B304, Items!A:F, 6, FALSE) * D304, "") -> 40.8
A305: b0bd3216 | B305: item-127 | C305: 45909.451 | D305: 20 | E305: 10485 | G305: =IF(D305<>"", VLOOKUP(B305, Items!A:F, 6, FALSE) * D305, "") -> 204
A306: 86111c13 | B306: item-133 | C306: 45908.357 | D306: -1 | E306: 10557 | G306: =IF(D306<>"", VLOOKUP(B306, Items!A:F, 6, FALSE) * D306, "") -> -48
A307: cc2d4bf3 | B307: item-132 | C307: 45908.357 | D307: -8 | E307: 10557 | G307: =IF(D307<>"", VLOOKUP(B307, Items!A:F, 6, FALSE) * D307, "") -> -80
A308: 2eba2982 | B308: item-129 | C308: 45908.357 | D308: -1 | E308: 10557 | G308: =IF(D308<>"", VLOOKUP(B308, Items!A:F, 6, FALSE) * D308, "") -> -22.54
A309: f131d751 | B309: item-128 | C309: 45908.357 | D309: -3 | E309: 10557 | G309: =IF(D309<>"", VLOOKUP(B309, Items!A:F, 6, FALSE) * D309, "") -> -62.67
... A1757: ab53137a | B1757: item-124 | C1757: 46059.468 | D1757: -3 | E1757: 10888 | G1757: =IF(D1757<>"", VLOOKUP(B1757, Items!A:F, 6, FALSE) * D1757, "") -> -87.45
A1758: 038d01d9 | B1758: item-127 | C1758: 46059.468 | D1758: -19 | E1758: 10888 | G1758: =IF(D1758<>"", VLOOKUP(B1758, Items!A:F, 6, FALSE) * D1758, "") -> -193.8 | I1758: =SUM(G1756:G1763) -> -1503.72
A1759: c29fe6fd | B1759: item-126 | C1759: 46059.468 | D1759: -3 | E1759: 10888 | G1759: =IF(D1759<>"", VLOOKUP(B1759, Items!A:F, 6, FALSE) * D1759, "") -> -342.66
A1760: 31d48b9c | B1760: item-125 | C1760: 46059.469 | D1760: -6 | E1760: 10888 | G1760: =IF(D1760<>"", VLOOKUP(B1760, Items!A:F, 6, FALSE) * D1760, "") -> -479.16
A1761: efb0b72b | B1761: item-128 | C1761: 46059.469 | D1761: -1 | E1761: 10888 | G1761: =IF(D1761<>"", VLOOKUP(B1761, Items!A:F, 6, FALSE) * D1761, "") -> -20.89
A1762: ac0a60ae | B1762: item-129 | C1762: 46059.469 | D1762: -4 | E1762: 10888 | G1762: =IF(D1762<>"", VLOOKUP(B1762, Items!A:F, 6, FALSE) * D1762, "") -> -90.16
A1763: 5f1b3572 | B1763: item-132 | C1763: 46059.469 | D1763: -3 | E1763: 10888 | G1763: =IF(D1763<>"", VLOOKUP(B1763, Items!A:F, 6, FALSE) * D1763, "") -> -30
A1764: c1c9eeba | B1764: item-123 | C1764: 46063.582 | D1764: -2 | E1764: 10910 | G1764: =IF(D1764<>"", VLOOKUP(B1764, Items!A:F, 6, FALSE) * D1764, "") -> -129.8
A1765: 86ca3f82 | B1765: item-124 | C1765: 46063.582 | D1765: -1 | E1765: 10910 | G1765: =IF(D1765<>"", VLOOKUP(B1765, Items!A:F, 6, FALSE) * D1765, "") -> -29.15
A1766: 3dcd798b | B1766: item-127 | C1766: 46063.583 | D1766: -15 | E1766: 10910 | G1766: =IF(D1766<>"", VLOOKUP(B1766, Items!A:F, 6, FALSE) * D1766, "") -> -153
A1767: 448ebe03 | B1767: item-126 | C1767: 46063.583 | D1767: -1 | E1767: 10910 | G1767: =IF(D1767<>"", VLOOKUP(B1767, Items!A:F, 6, FALSE) * D1767, "") -> -114.22
A1768: 36634c3b | B1768: item-125 | C1768: 46063.583 | D1768: -3 | E1768: 10910 | G1768: =IF(D1768<>"", VLOOKUP(B1768, Items!A:F, 6, FALSE) * D1768, "") -> -239.58
A1769: fd6455f7 | B1769: item-129 | C1769: 46063.583 | D1769: -1 | E1769: 10910 | G1769: =IF(D1769<>"", VLOOKUP(B1769, Items!A:F, 6, FALSE) * D1769, "") -> -22.54
...

Sheet Employee
A1: Name | B1: Role | C1: Phone Number | D1: Email Address | E1: Image URL
A2: Chris Muse | B2: Owner | C2: 256-648-1224 | D2: chrismuse@RiverCityRoofingSolutions.com | E2: https://drive.google.com/file/d/1-acX70RTyQzxpbV21L-RrDgRGoYwRI-r/view?usp=drive_link
A3: Michael Muse | B3: Owner | C3: 256-221-4290 | D3: michaelmuse@RiverCityRoofingSolutions.com | E3: https://drive.google.com/file/d/1-dKMcMxL8ECk0bmqQZNXJ4MJxZQLmjz5/view?usp=drive_link
A4: Sara | B4: Admin | C4: 256-810-3594 | D4: sara@RiverCityRoofingSolutions.com | E4: https://drive.google.com/file/d/112O-dHhhhWzSFXI4sFKVA8UxRWwlAnle/view?usp=drive_link
A5: Destin | B5: Admin | C5: 256-905-7738 | D5: destin@RiverCityRoofingSolutions.com | E5: https://drive.google.com/file/d/10bsLKG_Y277IJwFdPWdrovUE053v78cD/view?usp=drive_link
A6: Tia | B6: Admin | C6: 256-394-8396 | D6: tia@RiverCityRoofingSolutions.com | E6: https://drive.google.com/file/d/106gnoEXJl7ijl1XtHRzwK0UFW99QJZ2d/view?usp=drive_link
A7: John | B7: Production | C7: 256-654-0875 | D7: john@RiverCityRoofingSolutions.com | E7: https://drive.google.com/file/d/10oaNuJyucRObuF6dwiswwg6TSqc7l-u5/view?usp=drive_link
A8: Bart | B8: Production | C8: 256-654-0747 | D8: bart@RiverCityRoofingSolutions.com | E8: https://drive.google.com/file/d/115l-wgSHiYJ46rXzat5dE9dln7U6pGyG/view?usp=drive_link
A9: Tae | B9: Production | C9: 256-200-3467 | D9: tae@RiverCityRoofingSolutions.com | E9: https://drive.google.com/file/d/103Db4B-rJz2GBqO1wazWdFKAqON1ZM4g/view?usp=drive_link
A10: Hunter | B10: Sales Inspector | C10: 256-221-0548 | D10: hunter@RiverCityRoofingSolutions.com | E10: https://drive.google.com/file/d/106wFzq0Iz4zZqhGN41vmCrgRbqMpnOTl/view?usp=drive_link
A11: Rick | B11: Sales Inspector | C11: 256-701-7376 | D11: rick@RiverCityRoofingSolutions.com | E11: https://drive.google.com/file/d/1-KZ8OQaK5QbuK_VZDNejQJG8QIu8Ffaz/view?usp=drive_link
A12: Rudy | B12: Sales Inspector | C12: 256-654-3631 | D12: rudy@RiverCityRoofingSolutions.com | E12: https://drive.google.com/file/d/1-_bIdSogWNRuH8j0t-O1CISkAubPQAz5/view?usp=drive_link
... A18: Danny | B18: Sales Inspector | C18: 256-994-7623 | D18: danny@RiverCityRoofingSolutions.com | E18: https://drive.google.com/file/d/118mMMLX5JozBN9kshpHemBgUBikq2jhZ/view?usp=drive_link
A19: Martin | B19: Contractor | C19: 256-479-4149
A20: Roger | B20: Contractor | C20: 256-318-2815
A21: Daniel | B21: Contractor | C21: 256-606-3443
A22: Saul | B22: Contractor | C22: 256-893-6676
A23: Paul Spradlin | B23: Contractor | C23: 256-755-1027 | D23: prspradlin@gmail.com
A24: Patrick | B24: Contractor | C24: 205-612-7162 | D24: manuelpetee10@aol.com
A25: Advanced Building | B25: Vendor | C25: 256-852-6415 | D25: srsicorp@billtrust.com
A26: Beacon Roofing Supply | B26: Vendor | C26: 256-361-0912 | D26: beaconroofingsupply@billtrust.com
A27: Gulf Eagle Supply | B27: Vendor | C27: 256-355-1145 | D27: gulfeaglesupply@billtrust.com
A28: Littrell Lumber Mill | B28: Vendor | C28: 256-355-6768 | D28: amanda@littrelllumbermill.com
A29: Majestic Metals | B29: Vendor | C29: 256-771-0107 | D29: alcustservice@majesticmetalsinc.com
